File: Lab2DataXLS.csv
Specimen label,popler Parallel,,,Specimen label,popler cross,,,Specimen label,oak parallel,,,Specimen label,oak cross,
Anvil height,38.19,mm,,Anvil height,37.333,mm,,Anvil height,39.31,mm,,Anvil height,38.4233,mm
Width,38.0133,mm,,Width,38.2867,mm,,Width,38.5433,mm,,Width,38.43,mm
Thickness,37.8567,mm,,Thickness,37.4467,mm,,Thickness,38.4267,mm,,Thickness,38.9533,mm
Rate 1,2,mm/min,,Rate 1,2,mm/min,,Rate 1,2,mm/min,,Rate 1,2,mm/min
,,,,,,,,,,,,,,
Time,Extension,Load,,Time,Extension,Load,,Time,Extension,Load,,Time,Extension,Load
(sec),(mm),(N),,(sec),(mm),(N),,(sec),(mm),(N),,(sec),(mm),(N)
0,-0.00004,1.60236,,0,-0.00008,-1.23327,,0,-0.00016,-0.18339,,0,-0.00036,-0.35386
0.4,-0.00368,0.9973,,0.4,-0.00792,-0.18852,,0.4,-0.00656,0.91858,,0.4,-0.0076,0.44557
0.8,-0.01992,-1.90808,,0.8,-0.02292,-0.56159,,0.8,-0.02244,0.00237,,0.8,-0.02272,-1.013
1.2,-0.0368,-4.68179,,1.2,-0.03784,-1.03968,,1.2,-0.03792,-2.03618,,1.2,-0.03784,-4.12921
1.6,-0.05208,-9.47132,,1.6,-0.05204,-7.58952,,1.6,-0.05272,-7.51698,,1.6,-0.05248,-12.42447
2,-0.0662,-13.62287,,2,-0.06588,-21.40086,,2,-0.06664,-16.34598,,2,-0.06632,-22.89544
2.4,-0.07976,-20.11707,,2.4,-0.07976,-46.31878,,2.4,-0.07996,-27.82329,,2.4,-0.07992,-39.46481
2.8,-0.09316,-29.88971,,2.8,-0.0934,-60.77358,,2.8,-0.09336,-31.60334,,2.8,-0.09372,-59.47878
3.2,-0.10656,-40.38654,,3.2,-0.10684,-70.22018,,3.2,-0.10676,-44.10189,,3.2,-0.10712,-78.45977
3.6,-0.1198,-56.79054,,3.6,-0.12012,-73.54957,,3.6,-0.12004,-46.27132,,3.6,-0.12032,-95.83326
4,-0.13296,-72.41783,,4,-0.1334,-85.13817,,4,-0.13344,-49.38048,,4,-0.13364,-110.71913
4.4,-0.14608,-89.27326,,4.4,-0.14664,-123.02333,,4.4,-0.14684,-58.83884,,4.4,-0.147,-121.31158
4.8,-0.15952,-107.13113,,4.8,-0.15964,-181.48049,,4.8,-0.16016,-98.72884,,4.8,-0.1602,-135.6347
5.2,-0.17304,-139.04015,,5.2,-0.17272,-260.12484,,5.2,-0.1736,-160.45739,,5.2,-0.17348,-154.56474
5.6,-0.1868,-180.10892,,5.6,-0.18604,-358.47826,,5.6,-0.18692,-242.69368,,5.6,-0.18696,-180.87069
6,-0.20016,-224.36758,,6,-0.19944,-475.9083,,6,-0.20036,-348.02645,,6,-0.20036,-210.57972
6.4,-0.21352,-279.79317,,6.4,-0.21316,-615.92143,,6.4,-0.21356,-474.73381,,6.4,-0.21356,-254.70122
6.8,-0.22672,-347.06444,,6.8,-0.22676,-773.10745,,6.8,-0.22676,-619.21515,,6.8,-0.22672,-309.01544
7.2,-0.23972,-431.69982,,7.2,-0.2402,-942.19325,,7.2,-0.23996,-777.09788,,7.2,-0.24016,-371.12569
7.6,-0.25224,-529.26322,,7.6,-0.25328,-1121.31573,,7.6,-0.25316,-948.82967,,7.6,-0.25352,-439.87981
8,-0.26532,-649.78986,,8,-0.26632,-1312.22047,,8,-0.26624,-1135.31947,,8,-0.2668,-511.62397
8.4,-0.27884,-787.79506,,8.4,-0.27972,-1517.75321,,8.4,-0.27956,-1341.39685,,8.4,-0.28008,-589.34349
8.8,-0.29244,-941.94086,,8.8,-0.29312,-1735.52036,,8.8,-0.293,-1565.79148,,8.8,-0.29352,-675.22582
9.2,-0.30612,-1116.40943,,9.2,-0.30632,-1954.29157,,9.2,-0.30648,-1807.89344,,9.2,-0.30672,-765.62334
9.6,-0.31976,-1319.94598,,9.6,-0.3196,-2182.60102,,9.6,-0.31988,-2068.06716,,9.6,-0.32008,-863.39209
10,-0.33324,-1537.23974,,10,-0.33276,-2414.66463,,10,-0.33324,-2342.28428,,10,-0.33312,-961.64988
10.4,-0.34648,-1772.012,,10.4,-0.3462,-2658.66164,,10.4,-0.34656,-2637.58842,,10.4,-0.34636,-1071.33565
10.8,-0.35984,-2033.66708,,10.8,-0.35948,-2903.7239,,10.8,-0.35972,-2948.87703,,10.8,-0.35972,-1185.11338
11.2,-0.37328,-2315.22173,,11.2,-0.3728,-3157.82502,,11.2,-0.37312,-3286.78936,,11.2,-0.37296,-1306.96697
11.6,-0.38656,-2612.40527,,11.6,-0.38604,-3408.84477,,11.6,-0.3862,-3641.32412,,11.6,-0.3866,-1436.58593
12,-0.39964,-2933.91962,,12,-0.39948,-3667.99794,,12,-0.39944,-4014.86941,,12,-0.4,-1573.26106
12.4,-0.4128,-3270.1984,,12.4,-0.41288,-3930.17344,,12.4,-0.41268,-4408.03096,,12.4,-0.4136,-1716.18834
12.8,-0.42592,-3641.40533,,12.8,-0.426,-4187.47254,,12.8,-0.42592,-4820.98982,,12.8,-0.42696,-1866.5947
13.2,-0.4392,-4048.70845,,13.2,-0.43916,-4445.50663,,13.2,-0.4392,-5247.60038,,13.2,-0.44024,-2021.16072
13.6,-0.45268,-4490.87173,,13.6,-0.45256,-4714.1403,,13.6,-0.4526,-5690.94233,,13.6,-0.4536,-2181.29512
14,-0.466,-4975.54131,,14,-0.46608,-4983.38379,,14,-0.466,-6164.94976,,14,-0.4666,-2346.17293
14.4,-0.47932,-5492.5926,,14.4,-0.47948,-5250.78215,,14.4,-0.4792,-6639.45898,,14.4,-0.47976,-2518.41098
14.8,-0.4928,-6048.65253,,14.8,-0.49284,-5521.12125,,14.8,-0.49208,-7119.08862,,14.8,-0.49316,-2698.25924
15.2,-0.50612,-6634.26965,,15.2,-0.50632,-5791.92415,,15.2,-0.50552,-7637.33536,,15.2,-0.50644,-2885.8142
15.6,-0.51948,-7256.90871,,15.6,-0.51944,-6049.99438,,15.6,-0.51916,-8181.94076,,15.6,-0.51996,-3083.49524
16,-0.53268,-7892.46187,,16,-0.5326,-6310.28116,,16,-0.5326,-8739.53328,,16,-0.53348,-3284.98073
16.4,-0.54592,-8560.06294,,16.4,-0.54604,-6570.74675,,16.4,-0.54604,-9321.68812,,16.4,-0.54676,-3491.00195
16.8,-0.55912,-9248.58823,,16.8,-0.55932,-6827.81637,,16.8,-0.55944,-9921.13203,,16.8,-0.56008,-3703.60017
17.2,-0.57212,-9948.83105,,17.2,-0.57272,-7078.68859,,17.2,-0.57264,-10525.1722,,17.2,-0.5734,-3921.1534
17.6,-0.58532,-10672.10063,,17.6,-0.58616,-7326.39283,,17.6,-0.58568,-11148.45648,,17.6,-0.58708,-4152.45034
18,-0.59852,-11406.10948,,18,-0.59956,-7576.78077,,18,-0.599,-11802.31869,,18,-0.60036,-4384.61117
18.4,-0.6116,-12141.30148,,18.4,-0.613,-7813.99831,,18.4,-0.61212,-12454.7869,,18.4,-0.61356,-4616.94747
18.8,-0.62476,-12895.26522,,18.8,-0.62636,-8047.29387,,18.8,-0.6252,-13124.28117,,18.8,-0.62676,-4853.19793
19.2,-0.63832,-13673.14756,,19.2,-0.63968,-8276.68682,,19.2,-0.63856,-13819.35626,,19.2,-0.63996,-5097.01148
19.6,-0.6518,-14451.0746,,19.6,-0.65288,-8494.01876,,19.6,-0.652,-14528.75584,,19.6,-0.65328,-5347.05631
20,-0.66524,-15242.14447,,20,-0.66616,-8711.99518,,20,-0.66532,-15236.96035,,20,-0.6666,-5600.63384
20.4,-0.67872,-16033.98025,,20.4,-0.67928,-8920.92884,,20.4,-0.67848,-15948.0989,,20.4,-0.68004,-5864.50696
20.8,-0.692,-16812.01756,,20.8,-0.69272,-9128.26359,,20.8,-0.69176,-16670.36414,,20.8,-0.69336,-6128.71721
21.2,-0.7052,-17590.41399,,21.2,-0.7062,-9326.56899,,21.2,-0.70516,-17414.71291,,21.2,-0.70656,-6387.53548
21.6,-0.71844,-18379.35746,,21.6,-0.71952,-9512.10409,,21.6,-0.71856,-18166.73428,,21.6,-0.72008,-6657.91929
22,-0.73176,-19172.37043,,22,-0.73292,-9689.25655,,22,-0.73208,-18929.96132,,22,-0.73364,-6933.55501
22.4,-0.7448,-19956.84355,,22.4,-0.74612,-9848.0016,,22.4,-0.74516,-19690.78034,,22.4,-0.74704,-7205.69417
22.8,-0.75804,-20761.96969,,22.8,-0.7594,-10000.43079,,22.8,-0.75836,-20468.46002,,22.8,-0.7604,-7477.52339
23.2,-0.77168,-21592.29219,,23.2,-0.77296,-10146.9785,,23.2,-0.7716,-21247.80715,,23.2,-0.77372,-7752.65768
23.6,-0.78508,-22411.87245,,23.6,-0.78672,-10271.49558,,23.6,-0.785,-22044.76446,,23.6,-0.78692,-8022.16604
24,-0.79824,-23219.23077,,24,-0.80012,-10362.5834,,24,-0.79808,-22830.17486,,24,-0.8,-8293.13993
24.4,-0.81172,-24042.67192,,24.4,-0.81332,-10431.85815,,24.4,-0.81132,-23631.26725,,24.4,-0.81316,-8562.96942
24.8,-0.8252,-24869.0322,,24.8,-0.82656,-10481.86496,,24.8,-0.82472,-24440.34964,,24.8,-0.82616,-8823.97145
25.2,-0.83836,-25680.69696,,25.2,-0.8398,-10505.57047,,25.2,-0.83816,-25264.71317,,25.2,-0.83912,-9086.76088
25.6,-0.85152,-26494.08281,,25.6,-0.85312,-10481.5498,,25.6,-0.85136,-26074.90122,,25.6,-0.85284,-9360.60473
26,-0.86508,-27340.45088,,26,-0.8666,-10455.91608,,26,-0.86452,-26883.69453,,26,-0.86668,-9635.82546
26.4,-0.87872,-28188.08854,,26.4,-0.87992,-10447.18027,,26.4,-0.87832,-27748.19136,,26.4,-0.88024,-9901.65025
26.8,-0.89188,-29021.43002,,26.8,-0.89296,-10459.54823,,26.8,-0.892,-28599.08938,,26.8,-0.89344,-10157.02561
27.2,-0.9052,-29848.1226,,27.2,-0.90624,-10495.75284,,27.2,-0.9052,-29421.94641,,27.2,-0.9068,-10409.06534
27.6,-0.91868,-30699.718,,27.6,-0.91968,-10546.20147,,27.6,-0.91832,-30240.22877,,27.6,-0.92024,-10660.01952
28,-0.93172,-31527.33743,,28,-0.93348,-10585.30658,,28,-0.93172,-31090.6589,,28,-0.93344,-10905.36267
28.4,-0.94488,-32370.66865,,28.4,-0.94724,-10585.11063,,28.4,-0.94464,-31918.76411,,28.4,-0.94668,-11146.33605
28.8,-0.95832,-33224.8956,,28.8,-0.96052,-10601.1197,,28.8,-0.95792,-32756.24812,,28.8,-0.9598,-11385.49298
29.2,-0.97152,-34058.89273,,29.2,-0.9734,-10639.79492,,29.2,-0.97156,-33629.9032,,29.2,-0.97288,-11618.85411
29.6,-0.98472,-34908.63144,,29.6,-0.98632,-10693.39365,,29.6,-0.98508,-34498.45314,,29.6,-0.9862,-11856.0344
30,-0.99804,-35770.58315,,30,-0.9994,-10763.58408,,30,-0.99832,-35354.03907,,30,-0.99988,-12099.15355
30.4,-1.01188,-36671.20337,,30.4,-1.01268,-10840.05162,,30.4,-1.01152,-36207.30937,,30.4,-1.01344,-12329.26399
30.8,-1.02556,-37551.20337,,30.8,-1.02624,-10915.66235,,30.8,-1.02528,-37092.50987,,30.8,-1.02672,-12550.96048
31.2,-1.03904,-38417.89365,,31.2,-1.03956,-10984.14361,,31.2,-1.03872,-37959.9303,,31.2,-1.04016,-12768.3416
31.6,-1.05224,-39260.44703,,31.6,-1.053,-11045.37845,,31.6,-1.05176,-38803.75028,,31.6,-1.05352,-12978.99187
31.956,-1.0636,-40001.27316,,32,-1.0664,-11098.88554,,32,-1.06448,-39637.00533,,32,-1.06664,-13180.48537
,,,,32.4,-1.08,-11147.1273,,,,,,32.4,-1.07996,-13386.52372
,,,,32.8,-1.0936,-11186.02157,,,,,,32.8,-1.0936,-13592.76175
,,,,33.2,-1.10704,-11210.7113,,,,,,33.2,-1.10708,-13787.41115
,,,,33.6,-1.12028,-11220.0506,,,,,,33.6,-1.12028,-13973.51772
,,,,34,-1.13348,-11216.98916,,,,,,34,-1.13364,-14158.77342
,,,,34.4,-1.1468,-11193.31568,,,,,,34.4,-1.1468,-14332.74448
,,,,34.8,-1.15992,-11044.14016,,,,,,34.8,-1.16004,-14509.62722
,,,,35.2,-1.17276,-11036.05926,,,,,,35.2,-1.1734,-14682.32721
,,,,35.6,-1.18616,-11059.67537,,,,,,35.6,-1.187,-14853.00958
,,,,36,-1.19968,-11089.96943,,,,,,36,-1.20032,-15014.26697
,,,,36.4,-1.21312,-11114.27546,,,,,,36.4,-1.21376,-15172.21481
,,,,36.8,-1.2268,-11139.81903,,,,,,36.8,-1.22712,-15324.59557
,,,,37.2,-1.24044,-11159.91771,,,,,,37.2,-1.24052,-15469.80888
,,,,37.6,-1.25372,-11161.75503,,,,,,37.6,-1.25396,-15612.81532
,,,,38,-1.26668,-11161.05095,,,,,,38,-1.26712,-15746.01978
,,,,38.4,-1.28012,-11165.50937,,,,,,38.4,-1.2804,-15875.16516
,,,,38.8,-1.29328,-11160.0399,,,,,,38.8,-1.29348,-16000.80281
,,,,39.2,-1.30636,-11155.49579,,,,,,39.2,-1.30664,-16121.34129
,,,,39.6,-1.31984,-11161.62166,,,,,,39.6,-1.32008,-16244.29524
,,,,40,-1.33352,-11169.94247,,,,,,40,-1.33332,-16363.53433
,,,,40.4,-1.34696,-11172.48312,,,,,,40.4,-1.34656,-16474.73276
,,,,40.8,-1.36024,-11175.33743,,,,,,40.8,-1.35992,-16583.6826
,,,,41.2,-1.37364,-11184.33028,,,,,,41.2,-1.373,-16687.26802
,,,,41.6,-1.38696,-11190.39655,,,,,,41.6,-1.38652,-16795.00192
,,,,42,-1.40004,-11197.23395,,,,,,42,-1.40024,-16903.51516
,,,,42.4,-1.4136,-11215.87977,,,,,,42.4,-1.41396,-17001.99544
,,,,42.8,-1.42696,-11234.87279,,,,,,42.8,-1.4272,-17089.68729
,,,,43.2,-1.44028,-11252.09704,,,,,,43.2,-1.44048,-17174.12621
,,,,43.6,-1.4536,-11267.83788,,,,,,43.6,-1.45384,-17257.20763
,,,,44,-1.46684,-11282.67124,,,,,,44,-1.46684,-17333.28253
,,,,44.4,-1.47988,-11298.16622,,,,,,44.4,-1.4798,-17406.52621
,,,,44.8,-1.49324,-11315.29436,,,,,,44.8,-1.49328,-17487.77926
,,,,45.2,-1.50692,-11333.21747,,,,,,45.2,-1.50684,-17568.82817
,,,,45.6,-1.5202,-11338.7242,,,,,,45.6,-1.52028,-17642.34155
,,,,46,-1.53352,-11237.0491,,,,,,46,-1.53372,-17710.25211
,,,,46.4,-1.54684,-11262.33563,,,,,,46.4,-1.5472,-17777.77225
,,,,46.8,-1.56012,-11288.57583,,,,,,46.8,-1.56056,-17840.63876
,,,,47.2,-1.57352,-11312.65908,,,,,,47.2,-1.57388,-17899.34486
,,,,47.6,-1.58696,-11332.5052,,,,,,47.6,-1.58756,-17963.89222
,,,,48,-1.60032,-11351.11973,,,,,,48,-1.6008,-18016.59763
,,,,48.4,-1.61356,-11360.1096,,,,,,48.4,-1.61396,-18066.87415
,,,,48.8,-1.62692,-11371.4911,,,,,,48.8,-1.62712,-18112.41359
,,,,49.2,-1.6402,-11378.77852,,,,,,49.2,-1.6402,-18160.62033
,,,,49.6,-1.65332,-11383.83821,,,,,,49.6,-1.65348,-18205.05857
,,,,50,-1.66648,-11385.62858,,,,,,50,-1.6668,-18251.87206
,,,,50.4,-1.67976,-11386.88251,,,,,,50.4,-1.68028,-18301.98467
,,,,50.8,-1.69308,-11389.39708,,,,,,50.8,-1.69392,-18347.00108
,,,,51.2,-1.70636,-11388.94707,,,,,,51.2,-1.70716,-18382.55525
,,,,51.6,-1.71956,-11385.46839,,,,,,51.6,-1.7206,-18420.43549
,,,,52,-1.733,-11383.91346,,,,,,52,-1.73384,-18452.7263
,,,,52.4,-1.74632,-11381.17015,,,,,,52.4,-1.7472,-18484.13497
,,,,52.8,-1.75952,-11376.42562,,,,,,52.8,-1.7604,-18514.49758
,,,,53.2,-1.77308,-11377.02763,,,,,,53.2,-1.77364,-18543.51312
,,,,53.6,-1.78684,-11379.27994,,,,,,53.6,-1.78672,-18568.90321
,,,,54,-1.8004,-11375.19181,,,,,,54,-1.79988,-18601.0778
,,,,54.4,-1.81364,-11360.02168,,,,,,54.4,-1.81324,-18633.09294
,,,,54.8,-1.82676,-11347.16645,,,,,,54.8,-1.82664,-18662.51826
,,,,55.2,-1.83976,-11327.83741,,,,,,55.2,-1.84,-18689.46403
,,,,55.6,-1.85264,-11307.64335,,,,,,55.6,-1.85364,-18722.50438
,,,,56,-1.86624,-11300.52358,,,,,,56,-1.8672,-18748.50243
,,,,56.4,-1.87992,-11296.992,,,,,,56.4,-1.88044,-18764.09948
,,,,56.8,-1.89336,-11293.38965,,,,,,56.8,-1.89364,-18781.48317
,,,,57.2,-1.90684,-11299.77405,,,,,,57.2,-1.90696,-18800.10515
,,,,57.6,-1.9202,-11307.23134,,,,,,57.6,-1.92016,-18812.20937
,,,,58,-1.93368,-11317.38499,,,,,,58,-1.93344,-18831.72542
,,,,58.4,-1.94716,-11327.02902,,,,,,58.4,-1.94696,-18852.65112
,,,,58.8,-1.96036,-11334.68002,,,,,,58.8,-1.96016,-18865.9817
,,,,59.2,-1.97332,-11338.81509,,,,,,59.2,-1.97328,-18885.31148
,,,,59.6,-1.98632,-11348.0255,,,,,,59.6,-1.987,-18909.54226
,,,,60,-1.99972,-11362.95125,,,,,,60,-2.00048,-18928.60681
,,,,60.4,-2.0132,-11378.34266,,,,,,60.4,-2.01372,-18943.27253
,,,,60.8,-2.02648,-11389.33524,,,,,,60.8,-2.02712,-18956.78639
,,,,61.2,-2.0398,-11400.47312,,,,,,61.2,-2.04056,-18967.71193
,,,,61.6,-2.05344,-11409.86234,,,,,,61.6,-2.0538,-18975.71683
,,,,62,-2.06696,-11419.01165,,,,,,62,-2.06692,-18978.25897
,,,,62.4,-2.08028,-11421.92408,,,,,,62.4,-2.08008,-18986.68855
,,,,62.8,-2.09356,-11423.00889,,,,,,62.8,-2.09352,-19000.38272
,,,,63.2,-2.10692,-11425.76486,,,,,,63.2,-2.10712,-19014.71913
,,,,63.6,-2.12012,-11427.92925,,,,,,63.6,-2.12036,-19017.22401
,,,,64,-2.13356,-11436.32308,,,,,,64,-2.13384,-19029.20306
,,,,64.4,-2.14708,-11441.51986,,,,,,64.4,-2.14716,-19034.99663
,,,,64.8,-2.16028,-11443.96365,,,,,,64.8,-2.16028,-19042.67669
,,,,65.2,-2.17344,-11447.72843,,,,,,65.2,-2.17352,-19047.91892
,,,,65.60001,-2.1868,-11452.3761,,,,,,65.60001,-2.18668,-19052.73497
,,,,66,-2.19996,-11457.71965,,,,,,66,-2.19976,-19059.97247
,,,,66.4,-2.2132,-11462.09911,,,,,,66.4,-2.2132,-19068.71945
,,,,66.8,-2.22644,-11467.03064,,,,,,66.8,-2.22676,-19080.34384
,,,,67.20001,-2.23988,-11472.60964,,,,,,67.20001,-2.24024,-19092.86827
,,,,67.60001,-2.2532,-11479.11623,,,,,,67.60001,-2.25408,-19109.93606
,,,,68,-2.26652,-11491.24131,,,,,,68,-2.26752,-19115.36008
,,,,68.4,-2.27996,-11502.57587,,,,,,68.4,-2.28064,-19112.40667
,,,,68.8,-2.29324,-11511.16416,,,,,,68.8,-2.29352,-19111.66906
,,,,69.20001,-2.30664,-11520.75604,,,,,,69.20001,-2.30664,-19114.15309
,,,,69.60001,-2.31984,-11525.435,,,,,,69.60001,-2.32004,-19123.88951
,,,,70,-2.33312,-11531.34555,,,,,,70,-2.33324,-19131.31028
,,,,70.4,-2.34648,-11536.8396,,,,,,70.4,-2.34656,-19139.32711
,,,,70.8,-2.35992,-11542.3575,,,,,,70.8,-2.36008,-19148.91005
,,,,71.20001,-2.37336,-11551.89872,,,,,,71.20001,-2.3734,-19154.08671
,,,,71.60001,-2.38656,-11552.98501,,,,,,71.60001,-2.38696,-19165.1836
,,,,72,-2.39972,-11551.69532,,,,,,72,-2.40068,-19175.13162
,,,,72.4,-2.41312,-11555.22019,,,,,,72.4,-2.41436,-19178.76154
,,,,72.8,-2.4266,-11559.90139,,,,,,72.8,-2.42764,-19175.02135
,,,,73.20001,-2.44024,-11565.15256,,,,,,73.20001,-2.44088,-19170.2351
,,,,73.60001,-2.45372,-11565.72625,,,,,,73.60001,-2.45392,-19163.02443
,,,,74,-2.46704,-11568.72958,,,,,,74,-2.46668,-19152.79776
,,,,74.4,-2.48036,-11567.67607,,,,,,74.4,-2.4796,-19148.94879
,,,,74.8,-2.49356,-11567.46447,,,,,,74.8,-2.49316,-19156.02982
,,,,75.20001,-2.50688,-11568.45838,,,,,,75.20001,-2.50652,-19156.83895
,,,,75.60001,-2.52008,-11566.38712,,,,,,75.60001,-2.52024,-19163.82611
,,,,76,-2.53332,-11566.27461,,,,,,76,-2.53412,-19169.61372
,,,,76.4,-2.54672,-11570.1668,,,,,,76.4,-2.54776,-19165.66044
,,,,76.8,-2.56008,-11571.65915,,,,,,76.8,-2.56084,-19146.4752
,,,,77.20001,-2.57336,-11571.8171,,,,,,77.20001,-2.57376,-19129.55493
,,,,77.60001,-2.58664,-11573.61716,,,,,,77.60001,-2.58724,-19118.85738
,,,,78,-2.60024,-11580.37558,,,,,,78,-2.60052,-19105.83228
,,,,78.4,-2.61384,-11586.07528,,,,,,78.4,-2.6138,-19096.96311
,,,,78.8,-2.62704,-11585.98587,,,,,,78.8,-2.62728,-19087.09705
,,,,79.20001,-2.6406,-11593.62942,,,,,,79.20001,-2.64064,-19069.13668
,,,,79.60001,-2.65364,-11590.47261,,,,,,79.60001,-2.65376,-19050.46701
,,,,80,-2.66668,-11591.63043,,,,,,80,-2.66728,-19037.49853
,,,,80.4,-2.67972,-11594.08242,,,,,,80.4,-2.68112,-19027.1467
,,,,80.8,-2.69292,-11600.81625,,,,,,80.8,-2.69452,-19000.30077
,,,,81.20001,-2.70628,-11603.89632,,,,,,81.20001,-2.70744,-18968.82802
,,,,81.60001,-2.71944,-11610.59886,,,,,,81.60001,-2.72104,-18951.29383
,,,,82.00001,-2.73316,-11618.59781,,,,,,82.00001,-2.73424,-18925.76218
,,,,82.4,-2.74652,-11618.66561,,,,,,82.4,-2.74732,-18902.99618
,,,,82.8,-2.75976,-11621.35974,,,,,,82.8,-2.76056,-18885.36215
,,,,83.20001,-2.77324,-11629.39072,,,,,,83.20001,-2.77408,-18874.68696
,,,,83.60001,-2.7868,-11634.87956,,,,,,83.60001,-2.78708,-18856.90242
,,,,84.00001,-2.80012,-11638.55419,,,,,,84.00001,-2.80036,-18846.82029
,,,,84.4,-2.8132,-11635.077,,,,,,84.4,-2.814,-18842.54068
,,,,84.8,-2.82656,-11644.16298,,,,,,84.8,-2.82728,-18834.63413
,,,,85.20001,-2.83992,-11648.39491,,,,,,85.20001,-2.84048,-18818.64816
,,,,85.60001,-2.853,-11648.46048,,,,,,85.60001,-2.85396,-18806.3249
,,,,86.00001,-2.86632,-11654.31663,,,,,,86.00001,-2.86728,-18794.39652
,,,,86.4,-2.87968,-11659.88445,,,,,,86.4,-2.88056,-18777.68934
,,,,86.8,-2.893,-11665.78606,,,,,,86.8,-2.8938,-18761.93285
,,,,87.20001,-2.9064,-11669.25356,,,,,,87.20001,-2.90716,-18746.63383
,,,,87.60001,-2.91984,-11678.00799,,,,,,87.60001,-2.92048,-18727.4918
,,,,88.00001,-2.93328,-11684.03849,,,,,,88.00001,-2.93364,-18707.98171
,,,,88.4,-2.9468,-11688.58409,,,,,,88.4,-2.94716,-18693.28469
,,,,88.8,-2.96004,-11692.8041,,,,,,88.8,-2.96048,-18675.31836
,,,,89.20001,-2.97292,-11691.55017,,,,,,89.20001,-2.97368,-18653.59545
,,,,89.60001,-2.98604,-11697.09414,,,,,,89.60001,-2.987,-18640.51968
,,,,90.00001,-2.99936,-11710.269,,,,,,90.00001,-3.00052,-18626.92386
,,,,90.4,-3.01296,-11721.23551,,,,,,90.4,-3.01376,-18610.75312
,,,,90.8,-3.02652,-11731.54786,,,,,,90.8,-3.02696,-18598.34194
,,,,91.20001,-3.03992,-11737.84807,,,,,,91.20001,-3.04032,-18579.47856
,,,,91.60001,-3.05332,-11745.81423,,,,,,91.60001,-3.05352,-18567.78413
,,,,92.00001,-3.0666,-11749.09025,,,,,,92.00001,-3.06684,-18563.0694
,,,,92.4,-3.08004,-11755.83377,,,,,,92.4,-3.08036,-18561.20378
,,,,92.8,-3.09356,-11764.68655,,,,,,92.8,-3.09408,-18561.61803
,,,,93.20001,-3.10724,-11571.26874,,,,,,93.20001,-3.10764,-18558.85535
,,,,93.60001,-3.12028,-11584.56728,,,,,,93.60001,-3.12072,-18543.76346
,,,,94.00001,-3.13332,-11611.05335,,,,,,94.00001,-3.13396,-18529.17075
,,,,94.4,-3.1466,-11638.16676,,,,,,94.4,-3.14708,-18517.23492
,,,,94.8,-3.1598,-11661.69345,,,,,,94.8,-3.16036,-18506.09034
,,,,95.20001,-3.173,-11685.21568,,,,,,95.20001,-3.17368,-18488.48462
,,,,95.60001,-3.18652,-11708.13441,,,,,,95.60001,-3.18708,-18473.61773
,,,,96.00001,-3.19988,-11723.30454,,,,,,96.00001,-3.20036,-18450.99479
,,,,96.4,-3.2132,-11735.39981,,,,,,96.4,-3.21364,-18420.71712
,,,,96.8,-3.22644,-11744.69814,,,,,,96.8,-3.22696,-18397.31485
,,,,97.20001,-3.23976,-11755.47913,,,,,,97.20001,-3.24064,-18378.48872
,,,,97.60001,-3.25316,-11766.01648,,,,,,97.60001,-3.25424,-18354.32351
,,,,98.00001,-3.26644,-11778.71302,,,,,,98.00001,-3.2674,-18321.54095
,,,,98.4,-3.28004,-11789.5335,,,,,,98.4,-3.28048,-18290.87734
,,,,98.8,-3.29344,-11800.26606,,,,,,98.8,-3.29352,-18251.35052
,,,,99.20001,-3.30668,-11808.52875,,,,,,99.20001,-3.3068,-18218.07325
,,,,99.60001,-3.32004,-11817.0917,,,,,,99.60001,-3.32036,-18183.86316
,,,,100.00001,-3.3332,-11823.30549,,,,,,100.00001,-3.33384,-18141.02381
,,,,100.4,-3.34636,-11830.81046,,,,,,100.4,-3.3472,-18100.20208
,,,,100.8,-3.35976,-11840.54688,,,,,,100.8,-3.36068,-18061.95527
,,,,101.20001,-3.37312,-11850.71692,,,,,,101.20001,-3.37404,-18020.93387
,,,,101.60001,-3.38648,-11855.25283,,,,,,101.60001,-3.3874,-17977.76073
,,,,102.00001,-3.39956,-11856.22513,,,,,,102.00001,-3.40068,-17938.14003
,,,,102.4,-3.41304,-11864.66441,,,,,,102.4,-3.41424,-17893.89253
,,,,102.8,-3.42656,-11873.34508,,,,,,102.8,-3.4276,-17830.80101
,,,,103.20001,-3.43996,-11879.84571,,,,,,103.20001,-3.44088,-17723.54245
,,,,103.60001,-3.45364,-11889.23195,,,,,,103.60001,-3.45432,-17656.72565
,,,,104.00001,-3.46696,-11893.16809,,,,,,104.00001,-3.46752,-17610.11332
,,,,104.4,-3.48016,-11898.20617,,,,,,104.4,-3.48032,-17569.67902
,,,,104.8,-3.49348,-11903.83658,,,,,,104.8,-3.4936,-17548.84273
,,,,105.20001,-3.50684,-11909.90135,,,,,,105.20001,-3.50716,-17523.67765
,,,,105.60001,-3.51996,-11912.04414,,,,,,105.60001,-3.52044,-17493.67565
,,,,106.00001,-3.53312,-11913.00154,,,,,,106.00001,-3.53364,-17459.38212
,,,,106.4,-3.54672,-11924.2534,,,,,,106.4,-3.54716,-17393.77826
,,,,106.8,-3.5602,-11927.9936,,,,,,106.8,-3.56052,-17353.99812
,,,,107.20001,-3.57372,-11932.05789,,,,,,107.20001,-3.57356,-17326.6679
,,,,107.60001,-3.587,-11930.85536,,,,,,107.60001,-3.58696,-17281.20893
,,,,108.00001,-3.6002,-11934.17683,,,,,,108.00001,-3.60044,-17241.94586
,,,,108.4,-3.61344,-11935.05153,,,,,,108.4,-3.61388,-17184.21131
,,,,108.8,-3.6268,-11940.76836,,,,,,108.8,-3.62716,-17138.39024
,,,,109.20001,-3.6402,-11948.10942,,,,,,109.20001,-3.64056,-17060.23067
,,,,109.60001,-3.65332,-11949.14356,,,,,,109.60001,-3.65408,-17016.15304
,,,,110.00001,-3.66668,-11959.99831,,,,,,110.00001,-3.6672,-16970.36028
,,,,110.4,-3.68,-11967.59343,,,,,,110.4,-3.68048,-16939.86505
,,,,110.8,-3.69332,-11973.17839,,,,,,110.8,-3.69376,-16918.10191
,,,,111.20001,-3.70652,-11978.30066,,,,,,111.20001,-3.70688,-16901.88795
,,,,111.60001,-3.71996,-11987.13407,,,,,,111.60001,-3.72056,-16898.28932
,,,,112.00001,-3.7336,-11995.06223,,,,,,112.00001,-3.73404,-16892.90851
,,,,112.4,-3.74676,-11994.42893,,,,,,112.4,-3.74724,-16880.58525
,,,,112.8,-3.76024,-12004.2935,,,,,,112.8,-3.76044,-16864.20739
,,,,113.20001,-3.77376,-12015.2317,,,,,,113.20001,-3.77384,-16855.53342
,,,,113.60001,-3.787,-12016.92447,,,,,,113.60001,-3.78724,-16849.57296
,,,,114.00001,-3.8002,-12021.06699,,,,,,114.00001,-3.80072,-16850.75164
,,,,114.40001,-3.81352,-12025.31084,,,,,,114.40001,-3.8142,-16847.86826
,,,,114.8,-3.82688,-12033.16972,,,,,,114.8,-3.82744,-16837.69524
,,,,115.20001,-3.84008,-12035.80946,,,,,,115.20001,-3.84048,-16824.87875
,,,,115.60001,-3.85336,-12044.68533,,,,,,115.60001,-3.85384,-16733.34837
,,,,116.00001,-3.86692,-12057.16208,,,,,,116.00001,-3.86728,-16607.47528
,,,,116.40001,-3.88036,-12064.57019,,,,,,116.40001,-3.88068,-16531.33929
,,,,116.8,-3.89364,-12069.37507,,,,,,116.8,-3.89392,-16475.80713
,,,,117.20001,-3.90676,-12073.8849,,,,,,117.20001,-3.90752,-16442.9158
,,,,117.60001,-3.92008,-12082.80995,,,,,,117.60001,-3.92068,-16411.02433
,,,,118.00001,-3.93344,-12088.02536,,,,,,118.00001,-3.93436,-16397.17817
,,,,118.40001,-3.94716,-12100.21079,,,,,,118.40001,-3.94776,-16382.45732
,,,,118.8,-3.96056,-12104.60439,,,,,,118.8,-3.96076,-16363.83384
,,,,119.20001,-3.97364,-12108.15981,,,,,,119.20001,-3.97372,-16349.08468
,,,,119.60001,-3.98688,-12112.75384,,,,,,119.60001,-3.98692,-16344.40869
,,,,120.00001,-4.00012,-12119.29545,,,,,,120.00001,-4.00008,-16340.83688
,,,,120.40001,-4.01336,-12123.78442,,,,,,120.40001,-4.01328,-16339.75655
,,,,120.8,-4.02652,-12128.0089,,,,,,120.8,-4.02656,-16346.29965
,,,,121.20001,-4.03984,-12136.00785,,,,,,121.20001,-4.03988,-16350.47942
,,,,121.60001,-4.05316,-12143.02778,,,,,,121.60001,-4.05332,-16361.38409
,,,,122.00001,-4.06644,-12149.62378,,,,,,122.00001,-4.0668,-16374.67146
,,,,122.40001,-4.07988,-12157.33737,,,,,,122.40001,-4.08036,-16388.90654
,,,,122.8,-4.09336,-12162.97373,,,,,,122.8,-4.09372,-16396.59554
,,,,123.20001,-4.10676,-12168.34933,,,,,,123.20001,-4.107,-16405.64799
,,,,123.60001,-4.12008,-12171.68123,,,,,,123.60001,-4.1204,-16412.29987
,,,,124.00001,-4.13352,-12177.25873,,,,,,124.00001,-4.13376,-16420.41951
,,,,124.40001,-4.1468,-12180.21065,,,,,,124.40001,-4.14688,-16428.14726
,,,,124.8,-4.15996,-12185.71737,,,,,,124.8,-4.16004,-16437.88368
,,,,125.20001,-4.17316,-12186.40357,,,,,,125.20001,-4.1734,-16454.23621
,,,,125.60001,-4.18652,-12194.48224,,,,,,125.60001,-4.18684,-16467.48185
,,,,126.00001,-4.19992,-12201.11772,,,,,,126.00001,-4.2002,-16472.41861
,,,,126.40001,-4.21336,-12205.4711,,,,,,126.40001,-4.21368,-16481.15367
,,,,126.8,-4.22676,-12207.98492,,,,,,126.8,-4.22696,-16491.63663
,,,,127.20001,-4.24012,-12210.5591,,,,,,127.20001,-4.24036,-16498.84433
,,,,127.60001,-4.25336,-12212.06561,,,,,,127.60001,-4.25384,-16507.24858
,,,,128,-4.2666,-12214.44011,,,,,,128,-4.26712,-16515.74224
,,,,128.40001,-4.28016,-12227.43466,,,,,,128.40001,-4.28036,-16523.73224
,,,,128.8,-4.29376,-12235.92311,,,,,,128.8,-4.29344,-16527.36962
,,,,129.20002,-4.30712,-12241.14075,,,,,,129.20002,-4.30652,-16535.43264
,,,,129.60001,-4.32036,-12242.82458,,,,,,129.60001,-4.31988,-16549.04485
,,,,130,-4.33356,-12246.89558,,,,,,130,-4.33328,-16558.52497
,,,,130.40001,-4.3468,-12251.2266,,,,,,130.40001,-4.34672,-16576.01446
,,,,130.8,-4.36,-12256.20955,,,,,,130.8,-4.3604,-16594.68114
,,,,131.20002,-4.37336,-12267.15371,,,,,,131.20002,-4.3738,-16605.34889
,,,,131.6,-4.38668,-12269.67946,,,,,,131.6,-4.38736,-16622.34664
,,,,132,-4.39968,-12268.39498,,,,,,132,-4.40084,-16636.76798
,,,,132.40002,-4.413,-12274.8971,,,,,,132.40002,-4.41408,-16644.68497
,,,,132.8,-4.4264,-12283.65824,,,,,,132.8,-4.42716,-16650.4845
,,,,133.20002,-4.43992,-12293.24341,,,,,,133.20002,-4.4404,-16663.98048
,,,,133.6,-4.45348,-12300.22386,,,,,,133.6,-4.45384,-16678.3005
,,,,134,-4.46696,-12309.44544,,,,,,134,-4.46688,-16688.76559
,,,,134.40002,-4.48012,-12313.48962,,,,,,134.40002,-4.47992,-16704.49674
,,,,134.8,-4.49324,-12320.02154,,,,,,134.8,-4.4934,-16724.02918
,,,,135.20002,-4.50652,-12322.52941,,,,,,135.20002,-4.5068,-16741.54699
,,,,135.6,-4.51944,-12323.12024,,,,,,135.6,-4.52004,-16755.71799
,,,,136,-4.53244,-12327.38197,,,,,,136,-4.53344,-16769.11712
,,,,136.40002,-4.54604,-12338.16966,,,,,,136.40002,-4.54704,-16783.44011
,,,,136.8,-4.55964,-12348.08788,,,,,,136.8,-4.56248,-14974.05618
,,,,137.20002,-4.57316,-12356.21199,,,,,,137.20002,-4.5752,-14487.85365
,,,,137.6,-4.58668,-12360.53035,,,,,,137.6,-4.58792,-14276.17669
,,,,138,-4.6004,-12371.9275,,,,,,138,-4.60068,-14156.3043
,,,,138.40002,-4.61376,-12374.95318,,,,,,138.40002,-4.61384,-14085.42544
,,,,138.8,-4.62684,-12374.27741,,,,,,138.8,-4.6272,-14049.0517
,,,,139.20002,-4.63992,-12374.8906,,,,,,139.20002,-4.64048,-14030.72476
,,,,139.6,-4.65292,-12378.3417,,,,,,139.6,-4.65364,-14060.84299
,,,,140,-4.66628,-12385.93981,,,,,,140,-4.66704,-14138.9817
,,,,140.40002,-4.67976,-12398.16025,,,,,,140.40002,-4.6804,-14225.22515
,,,,140.8,-4.69332,-12411.82387,,,,,,140.8,-4.69344,-14308.32446
,,,,141.20002,-4.7068,-12417.29781,,,,,,141.20002,-4.70636,-14387.51519
,,,,141.6,-4.72,-12419.82952,,,,,,141.6,-4.71992,-14480.15273
,,,,142,-4.7332,-12421.84341,,,,,,142,-4.7334,-14571.39999
,,,,142.40002,-4.74648,-12425.54933,,,,,,142.40002,-4.74688,-14660.26008
,,,,142.8,-4.75972,-12431.14024,,,,,,142.8,-4.76056,-14747.62112
,,,,143.20002,-4.7732,-12440.9169,,,,,,143.20002,-4.77404,-14829.40465
,,,,143.6,-4.78688,-12453.66409,,,,,,143.6,-4.78788,-14416.03899
,,,,144,-4.80052,-12463.71791,,,,,,144,-4.80088,-14331.58517
,,,,144.40002,-4.8136,-12462.20544,,,,,,144.40002,-4.81424,-14286.50022
,,,,144.8,-4.82692,-12465.92477,,,,,,144.8,-4.82728,-14293.26832
,,,,145.20002,-4.84008,-12466.6214,,,,,,145.20002,-4.84056,-14355.30484
,,,,145.6,-4.85348,-12475.91004,,,,,,145.6,-4.85392,-14424.94839
,,,,146,-4.867,-12483.18478,,,,,,146,-4.86728,-14500.15754
,,,,146.40002,-4.88048,-12489.91564,,,,,,146.40002,-4.8804,-14569.54479
,,,,146.8,-4.89348,-12486.74765,,,,,,146.8,-4.89352,-14635.36769
,,,,147.20002,-4.9066,-12489.37473,,,,,,147.20002,-4.90688,-14712.3754
,,,,147.6,-4.9198,-12492.69024,,,,,,147.6,-4.92064,-14790.10731
,,,,148,-4.9332,-12498.62835,,,,,,148,-4.93408,-14858.54983
,,,,148.40002,-4.9468,-12504.54932,,,,,,148.40002,-4.94728,-14924.14623
,,,,148.8,-4.96024,-12269.15121,,,,,,148.8,-4.96116,-14558.09921
,,,,149.20002,-4.97336,-12208.66218,,,,,,149.20002,-4.97424,-14499.20088
,,,,149.6,-4.98636,-12218.35762,,,,,,149.6,-4.987,-14534.18732
,,,,150,-4.99968,-12243.55996,,,,,,150,-5.00032,-14593.82623
,,,,150.40002,-5.01312,-12269.87988,,,,,,150.40002,-5.01376,-14660.2124
,,,,150.8,-5.02656,-12295.4227,,,,,,150.8,-5.0268,-14724.62714
,,,,151.20002,-5.0398,-12315.64134,,,,,,151.20002,-5.0402,-14788.21188
,,,,151.6,-5.05316,-12336.90679,,,,,,151.6,-5.05368,-14858.78229
,,,,152,-5.06628,-12351.08897,,,,,,152,-5.06728,-14929.97557
,,,,152.40002,-5.07984,-12371.87907,,,,,,152.40002,-5.08064,-14992.30713
,,,,152.8,-5.09324,-12389.33951,,,,,,152.8,-5.09408,-15052.94889
,,,,153.20002,-5.10672,-12405.12133,,,,,,153.20002,-5.108,-14650.73973
,,,,153.6,-5.11996,-12415.83228,,,,,,153.6,-5.121,-14565.77182
,,,,154,-5.13324,-12424.85046,,,,,,154,-5.13416,-14532.29785
,,,,154.40002,-5.14644,-12433.17202,,,,,,154.40002,-5.14712,-14573.95703
,,,,154.8,-5.15976,-12443.77643,,,,,,154.8,-5.16024,-14632.65419
,,,,155.20002,-5.17284,-12454.34135,,,,,,155.20002,-5.17372,-14701.91181
,,,,155.6,-5.18616,-12466.42172,,,,,,155.6,-5.18716,-14771.75504
,,,,156,-5.19944,-12476.20955,,,,,,156,-5.20044,-14832.95262
,,,,156.40002,-5.21292,-12489.27638,,,,,,156.40002,-5.21368,-14893.15331
,,,,156.8,-5.22648,-12503.21865,,,,,,156.8,-5.22708,-14958.56196
,,,,157.20002,-5.24004,-12514.51969,,,,,,157.20002,-5.24112,-14625.41074
,,,,157.6,-5.25336,-12520.52039,,,,,,157.6,-5.25456,-14551.10162
,,,,158,-5.26684,-12530.94226,,,,,,158,-5.26772,-14482.62632
,,,,158.40002,-5.28048,-12541.21363,,,,,,158.40002,-5.28076,-14520.88505
,,,,158.8,-5.2938,-12547.42891,,,,,,158.8,-5.29388,-14570.57297
,,,,159.20002,-5.30684,-12550.40914,,,,,,159.20002,-5.307,-14629.99135
,,,,159.6,-5.32012,-12558.13837,,,,,,159.6,-5.32032,-14689.80759
,,,,160,-5.3334,-12564.21804,,,,,,160,-5.33344,-14744.49933
,,,,160.40002,-5.3466,-12570.0444,,,,,,160.40002,-5.3468,-14809.03774
,,,,160.8,-5.35984,-12574.84555,,,,,,160.8,-5.36032,-14874.01277
,,,,161.20002,-5.3732,-12585.14971,,,,,,161.20002,-5.37416,-14467.33177
,,,,161.6,-5.38648,-12587.85427,,,,,,161.6,-5.38752,-14382.38919
,,,,162.00002,-5.3996,-12588.44733,,,,,,162.00002,-5.40088,-14383.07017
,,,,162.40002,-5.41332,-12598.95861,,,,,,162.40002,-5.41416,-14431.32758
,,,,162.8,-5.42668,-12604.86394,,,,,,162.8,-5.42708,-14486.0208
,,,,163.20002,-5.44,-12609.20912,,,,,,163.20002,-5.4402,-14546.98741
,,,,163.6,-5.45344,-12613.3278,,,,,,163.6,-5.4536,-14613.10089
,,,,164.00002,-5.4666,-12617.02478,,,,,,164.00002,-5.46676,-14677.6706
,,,,164.40002,-5.47968,-12618.33757,,,,,,164.40002,-5.48016,-14746.68235
,,,,164.8,-5.49296,-12624.55434,,,,,,164.8,-5.4942,-14418.07896
,,,,165.20002,-5.50636,-12630.27042,,,,,,165.20002,-5.50768,-14343.59848
,,,,165.6,-5.51964,-12634.66626,,,,,,165.6,-5.52072,-14355.4166
,,,,166.00002,-5.533,-12639.89061,,,,,,166.00002,-5.53376,-14404.23578
,,,,166.40002,-5.54644,-12644.76031,,,,,,166.40002,-5.547,-14463.11474
,,,,166.8,-5.55996,-12650.51216,,,,,,166.8,-5.56024,-14525.83224
,,,,167.20002,-5.57336,-12651.4256,,,,,,,,
,,,,167.6,-5.58664,-12654.45352,,,,,,,,
,,,,168.00002,-5.60048,-12375.65354,,,,,,,,
,,,,168.40002,-5.61368,-12333.00939,,,,,,,,
,,,,168.8,-5.6268,-12334.00032,,,,,,,,
,,,,169.20002,-5.64,-12345.25368,,,,,,,,
,,,,169.6,-5.65324,-12359.40978,,,,,,,,
,,,,170.00002,-5.66636,-12374.57097,,,,,,,,
,,,,170.40002,-5.6798,-12393.35909,,,,,,,,
,,,,170.8,-5.69348,-12412.91687,,,,,,,,
,,,,171.20002,-5.70692,-12423.54438,,,,,,,,
,,,,171.6,-5.7202,-12434.19424,,,,,,,,
,,,,172.00002,-5.7336,-12442.18796,,,,,,,,
,,,,172.40002,-5.74668,-12447.10907,,,,,,,,
,,,,172.8,-5.75976,-12452.54651,,,,,,,,
,,,,173.20002,-5.77308,-12464.14632,,,,,,,,
,,,,173.6,-5.78668,-12481.19399,,,,,,,,
,,,,174.00002,-5.8002,-12493.42859,,,,,,,,
,,,,174.40002,-5.81364,-12500.15646,,,,,,,,
,,,,174.8,-5.82704,-12511.62142,,,,,,,,
,,,,175.20002,-5.84012,-12515.08743,,,,,,,,
,,,,175.6,-5.85324,-12522.63784,,,,,,,,
,,,,176.00002,-5.86656,-12533.32943,,,,,,,,
,,,,176.40002,-5.87984,-12543.5248,,,,,,,,
,,,,176.8,-5.89308,-12552.16449,,,,,,,,
,,,,177.20002,-5.90624,-12560.95022,,,,,,,,
,,,,177.6,-5.91952,-12573.77118,,,,,,,,
,,,,178.00002,-5.933,-12586.58022,,,,,,,,
,,,,178.40002,-5.9468,-12604.2515,,,,,,,,
,,,,178.8,-5.96044,-12617.32131,,,,,,,,
,,,,179.20002,-5.9738,-12625.8567,,,,,,,,
,,,,179.6,-5.987,-12632.89154,,,,,,,,
,,,,180.00002,-6.0004,-12643.83644,,,,,,,,
,,,,180.40002,-6.01388,-12657.10741,,,,,,,,
,,,,180.8,-6.02704,-12395.81481,,,,,,,,
,,,,181.20002,-6.04,-12353.05965,,,,,,,,
,,,,181.6,-6.05324,-12356.60687,,,,,,,,
,,,,182.00002,-6.0666,-12372.09365,,,,,,,,
,,,,182.40002,-6.08004,-12391.61864,,,,,,,,
,,,,182.8,-6.09356,-12412.97796,,,,,,,,
,,,,183.20002,-6.1074,-12436.00771,,,,,,,,
,,,,183.6,-6.12048,-12448.83761,,,,,,,,
,,,,184.00002,-6.13384,-12466.45004,,,,,,,,
,,,,184.40002,-6.14724,-12482.17225,,,,,,,,
,,,,184.8,-6.16028,-12495.71592,,,,,,,,
,,,,185.20002,-6.17332,-12509.30429,,,,,,,,
,,,,185.6,-6.18652,-12521.60072,,,,,,,,
,,,,186.00002,-6.1998,-12538.5195,,,,,,,,
,,,,186.40002,-6.21304,-12552.25837,,,,,,,,
,,,,186.8,-6.22648,-12567.48587,,,,,,,,
,,,,187.20002,-6.24008,-12584.3823,,,,,,,,
,,,,187.6,-6.25356,-12599.24918,,,,,,,,
,,,,188.00002,-6.267,-12614.36045,,,,,,,,
,,,,188.40002,-6.2806,-12629.98283,,,,,,,,
,,,,188.8,-6.29384,-12638.83114,,,,,,,,
,,,,189.20002,-6.30688,-12646.33536,,,,,,,,
,,,,189.6,-6.31996,-12653.04238,,,,,,,,
,,,,190.00002,-6.333,-12663.54918,,,,,,,,
,,,,190.40002,-6.34624,-12673.15149,,,,,,,,
,,,,190.8,-6.35968,-12685.41664,,,,,,,,
,,,,191.20002,-6.3732,-12703.11177,,,,,,,,
,,,,191.6,-6.38668,-12714.7615,,,,,,,,
,,,,192.00002,-6.40008,-12723.39672,,,,,,,,
,,,,192.40002,-6.4136,-12732.38957,,,,,,,,
,,,,192.8,-6.42696,-12743.76214,,,,,,,,
,,,,193.20002,-6.44024,-12750.23669,,,,,,,,
,,,,193.6,-6.45364,-12761.37829,,,,,,,,
,,,,194.00002,-6.46696,-12772.43495,,,,,,,,
,,,,194.40002,-6.47984,-12772.58843,,,,,,,,
,,,,194.8,-6.49288,-12779.70076,,,,,,,,
,,,,195.20002,-6.50636,-12791.42201,,,,,,,,
,,,,195.6,-6.51972,-12799.78305,,,,,,,,
,,,,196.00002,-6.53308,-12807.98316,,,,,,,,
,,,,196.40002,-6.54684,-12823.31795,,,,,,,,
,,,,196.8,-6.56024,-12827.08496,,,,,,,,
,,,,197.20002,-6.57348,-12829.89383,,,,,,,,
,,,,197.6,-6.58656,-12832.27503,,,,,,,,
,,,,198.00002,-6.6,-12838.40388,,,,,,,,
,,,,198.40002,-6.61336,-12846.77833,,,,,,,,
,,,,198.8,-6.6268,-12853.2365,,,,,,,,
,,,,199.20002,-6.6402,-12860.44121,,,,,,,,
,,,,199.6,-6.65356,-12866.5328,,,,,,,,
,,,,200.00002,-6.66712,-12562.58637,,,,,,,,
,,,,200.40002,-6.68036,-12492.12623,,,,,,,,
,,,,200.8,-6.69348,-12488.73398,,,,,,,,
,,,,201.20002,-6.70672,-12499.47622,,,,,,,,
,,,,201.6,-6.71992,-12516.62225,,,,,,,,
,,,,202.00002,-6.73344,-12534.44105,,,,,,,,
,,,,202.40002,-6.74684,-12552.59067,,,,,,,,
,,,,202.8,-6.75984,-12566.43534,,,,,,,,
,,,,203.20002,-6.77308,-12583.20957,,,,,,,,
,,,,203.6,-6.78672,-12604.58529,,,,,,,,
,,,,204.00002,-6.80024,-12620.93186,,,,,,,,
,,,,204.40002,-6.81348,-12632.82597,,,,,,,,
,,,,204.8,-6.82692,-12648.02068,,,,,,,,
,,,,205.20002,-6.83996,-12657.37116,,,,,,,,
,,,,205.6,-6.85308,-12669.95221,,,,,,,,
,,,,206.00002,-6.86632,-12681.91934,,,,,,,,
,,,,206.40002,-6.87972,-12697.88742,,,,,,,,
,,,,206.8,-6.89316,-12712.23724,,,,,,,,
,,,,207.20002,-6.90664,-12724.52623,,,,,,,,
,,,,207.6,-6.92012,-12735.01664,,,,,,,,
,,,,208.00002,-6.93364,-12743.40749,,,,,,,,
,,,,208.40002,-6.94724,-12754.50885,,,,,,,,
,,,,208.8,-6.96044,-12756.31338,,,,,,,,
,,,,209.20002,-6.97332,-12757.7588,,,,,,,,
,,,,209.6,-6.98628,-12762.7492,,,,,,,,
,,,,210.00002,-6.99956,-12772.03858,,,,,,,,
,,,,210.40002,-7.01304,-12783.55569,,,,,,,,
,,,,210.8,-7.0262,-12788.60122,,,,,,,,
,,,,211.20002,-7.0394,-12795.9758,,,,,,,,
,,,,211.6,-7.05268,-12805.55725,,,,,,,,
,,,,212.00002,-7.066,-12812.17337,,,,,,,,
,,,,212.40002,-7.07956,-12825.03307,,,,,,,,
,,,,212.8,-7.09332,-12838.98056,,,,,,,,
,,,,213.20002,-7.107,-12847.21345,,,,,,,,
,,,,213.6,-7.12024,-12849.23851,,,,,,,,
,,,,214.00002,-7.13348,-12854.03222,,,,,,,,
,,,,214.40002,-7.14676,-12857.45651,,,,,,,,
,,,,214.8,-7.16008,-12567.68852,,,,,,,,
,,,,215.20002,-7.17316,-12499.60288,,,,,,,,
,,,,215.6,-7.18644,-12497.85349,,,,,,,,
,,,,216.00002,-7.1998,-12504.02331,,,,,,,,
,,,,216.40002,-7.21308,-12515.96212,,,,,,,,
,,,,216.8,-7.2266,-12533.73474,,,,,,,,
,,,,217.20002,-7.24028,-12551.21678,,,,,,,,
,,,,217.6,-7.25352,-12562.41053,,,,,,,,
,,,,218.00002,-7.26672,-12574.25398,,,,,,,,
,,,,218.40002,-7.28028,-12592.41104,,,,,,,,
,,,,218.8,-7.29356,-12603.14286,,,,,,,,
,,,,219.20002,-7.30668,-12611.96434,,,,,,,,
,,,,219.6,-7.3198,-12621.83785,,,,,,,,
,,,,220.00002,-7.33292,-12629.00233,,,,,,,,
,,,,220.40002,-7.3464,-12643.15397,,,,,,,,
,,,,220.8,-7.35996,-12657.1849,,,,,,,,
,,,,221.20002,-7.37336,-12670.10868,,,,,,,,
,,,,221.6,-7.38664,-12678.98977,,,,,,,,
,,,,222.00002,-7.39968,-12682.28143,,,,,,,,
,,,,222.40002,-7.41312,-12694.44823,,,,,,,,
,,,,222.8,-7.42628,-12702.60811,,,,,,,,
,,,,223.20002,-7.43936,-12711.29996,,,,,,,,
,,,,223.6,-7.45288,-12728.61958,,,,,,,,
,,,,224.00002,-7.46644,-12744.87227,,,,,,,,
,,,,224.40002,-7.47972,-12757.32368,,,,,,,,
,,,,224.8,-7.49312,-12775.61933,,,,,,,,
,,,,225.20002,-7.5066,-12788.77258,,,,,,,,
,,,,225.6,-7.52012,-12805.24284,,,,,,,,
,,,,226.00002,-7.53332,-12815.86587,,,,,,,,
,,,,226.40002,-7.5468,-12829.35888,,,,,,,,
,,,,226.80002,-7.56008,-12837.331,,,,,,,,
,,,,227.20002,-7.57344,-12846.96013,,,,,,,,
,,,,227.6,-7.58648,-12849.33686,,,,,,,,
,,,,228.00002,-7.60008,-12862.57803,,,,,,,,
,,,,228.40002,-7.6134,-12867.66529,,,,,,,,
,,,,228.80002,-7.62728,-12546.75835,,,,,,,,
,,,,229.20002,-7.64052,-12519.35363,,,,,,,,
,,,,229.6,-7.65368,-12520.77669,,,,,,,,
,,,,230.00002,-7.66668,-12529.06173,,,,,,,,
,,,,230.40002,-7.6798,-12542.29397,,,,,,,,
,,,,230.80002,-7.69304,-12560.66561,,,,,,,,
,,,,231.20002,-7.70652,-12583.05162,,,,,,,,
,,,,231.6,-7.71976,-12603.89686,,,,,,,,
,,,,232.00002,-7.73324,-12620.35817,,,,,,,,
,,,,232.40002,-7.74652,-12638.1129,,,,,,,,
,,,,232.80002,-7.75992,-12655.59942,,,,,,,,
,,,,233.20002,-7.77332,-12671.53323,,,,,,,,
,,,,233.6,-7.7868,-12689.60238,,,,,,,,
,,,,234.00002,-7.80016,-12705.29926,,,,,,,,
,,,,234.40002,-7.81336,-12716.62563,,,,,,,,
,,,,234.80002,-7.82644,-12728.63746,,,,,,,,
,,,,235.20002,-7.83968,-12743.42686,,,,,,,,
,,,,235.6,-7.85292,-12761.52134,,,,,,,,
,,,,236.00002,-7.86636,-12778.59807,,,,,,,,
,,,,236.40002,-7.87972,-12793.8807,,,,,,,,
,,,,236.80002,-7.89292,-12803.44874,,,,,,,,
,,,,237.20002,-7.90644,-12818.68815,,,,,,,,
,,,,237.6,-7.92004,-12835.07049,,,,,,,,
,,,,238.00002,-7.93372,-12848.59031,,,,,,,,
,,,,238.40002,-7.9474,-12859.17163,,,,,,,,
,,,,238.80002,-7.96072,-12865.26769,,,,,,,,
,,,,239.20002,-7.97368,-12867.77556,,,,,,,,
,,,,239.6,-7.98648,-12870.78112,,,,,,,,
,,,,240.00002,-7.9996,-12881.60086,,,,,,,,
,,,,240.40002,-8.01312,-12896.64954,,,,,,,,
,,,,240.49602,-8.01632,-12899.44798,,,,,,,,